Workbook
Name ACTION: #REF!

Sheet Cover
C2: TEST CASE
B4: Project Name | C4: Quản lí tiêm chủng cho gia súc và gia cầm cho các hộ chăn nuôi của quận/huyện | F4: Creator | G4: Võ Văn Hoan Lê Thị Thanh Nga Trương Thanh Hữu Lê Trường Lâm Tạ Quang Hoàng
B5: Project Code | C5: SE04 | F5: Reviewer/Approver
B6: Document Code | C6: =C5&"_"&"Blackbox testcase"&F9&"v2.0" -> SE04_Blackbox testcasev2.0 | F6: Issue Date | G6: 42982
F7: Version | G7: 2
B10: Record of change
B11: Effective Date | C11: Version | D11: Change Item | E11: *A,D,M | F11: Change description | G11: Reference
B12: 26/03/2017 | C12: 1.0 | E12: A | G12: Blackbox testcase-template
B13: 42982 | C13: 2.0 | E13: M,D | F13: Bổ sung các màn hình cho các chức năng. Bổ sung các case còn thiếu và xóa bớt một số case dư thừa | G13: Blackbox testcase-template

Sheet Test case List
D1: TEST CASE LIST
B3: Project Name | D3: =Cover!C4 -> Quản lí tiêm chủng cho gia súc và gia cầm cho các hộ chăn nuôi của quận/huyện
B4: Project Code | D4: =Cover!C5 -> SE04
B5: Test Environment Setup Description | D5: 1. Apache Tomcat 9 2. Eclipse 3. MySQL 4. Web Browser
B8: No | C8: Function Name | D8: Sheet Name | E8: Description | F8: Pre-Condition
B9: 1 | C9: Function - Tìm kiếm cán bộ | D9: Quản lí cán bộ | E9: Check GUI và FUNC chức năng tiềm kiếm cán bộ | F9: Tại Menu Ứng dụng: 1. Click [Cán bộ] 2. Click [Danh sách].
B10: 2 | C10: Function - Chỉnh sửa thông tin cán bộ | D10: Quản lí cán bộ | E10: Check GUI và FUNC chức năng chỉnh sửa thông tin cán bộ | F10: C1:Tại màn hình Danh sách cán bộ: Click [Sửa] Button ngay tại cán bộ cần sửa. C2: Tại màn hình Xem cán bộ: Click [Sửa]Button.
B11: 3 | C11: Function - Thêm cán bộ | D11: Quản lí cán bộ | E11: Check GUI và FUNC chức năng thêm cán bộ | F11: Tại Menu Ứng dụng: 1. Click [Cán bộ] 2. Click [Thêm mới]
B12: 4 | C12: Function - Xóa cán bộ | D12: Quản lí cán bộ | E12: Check GUI và FUNC chức năng xóa cán bộ | F12: Tại màn hình Danh sách cán bộ: Click [Xóa] ngay tại cán bộ muốn xóa.
B13: 5 | C13: Layout QL Cán bộ | D13: Layout QL cán bộ | E13: GUI chức năng Quản lý Cán bộ

Sheet Quản lí cán bộ
A2: Module Code | B2: Quản lí cán bộ
A3: Test requirement | B3: 1. Tìm kiếm cán bộ. 2. Thêm cán bộ 3. Chỉnh sửa thông tin cán bộ 4. Xóa cán bộ
A4: Tester | B4: Lê Trường Lâm
A5: Pass | B5: Fail | C5: Untested | D5: N/A | E5: Number of Test cases
A6: =COUNTIF(F11:F1147,"Pass") -> 0 | B6: =COUNTIF(F11:F1147,"Fail") -> 0 | C6: =E6-D6-B6-A6 -> 104 | D6: =COUNTIF(F$11:F$1147,"N/A") -> 0 | E6: =COUNTA(A11:A1147) -> 104
A8: ID | B8: Test Case Description | C8: Test Case Procedure | D8: Expected Output | E8: Inter-test case Dependence | F8: Result | G8: Test date | H8: Note
B9: Function : Tìm kiếm cán bộ
B10: Check GUI-Tìm kiếm cán bộ
A11: GUI-SearchCB-01 | B11: [Thêm] Button
C12: Nếu người dùng không có quyền thêm cán bộ | D12: Status = disable
C13: Trường hợp khác | D13: Status = enable
A14: GUI-SearchCB-02 | B14: [Search] Search | D14: Status = enable
A15: GUI-SearchCB-03 | B15: [Result]Grid | D15: Format: 10 bản ghi trong 1 trang
C16: [Họ tên]Column | D16: Lấy dữ liệu từ cột Họ tên của bảng Họ tên
C17: [Ngày sinh]Column | D17: Lấy dữ liệu từ cột Ngày sinh của bảng Ngày sinh
A18: GUI-SearchCB-04 | B18: [Sửa]Button | C18: Nếu người dùng không có quyền sửa thông tin cán bộ | D18: Status = disable
C19: Trường hợp khác | D19: Status = enable
A20: GUI-SearchCB-05 | B20: [Xóa]Button | C20: Nếu người dùng không có quyền xóa cán bộ | D20: Statuss = disable
C21: Trường hợp khác | D21: Status = enable
A22: GUI-SearchCB-06 | B22: [Đầu]Button | C22: Nếu người quản lí đang ở trang đầu tiên của danh sách. | D22: Status = disable
C23: Trường hợp khác | D23: Status = enable
A24: GUI-SearchCB-07 | B24: [Trước]Button | C24: Nếu người quản lí đang ở trang đâu tiên của danh sách. | D24: Status = disable
C25: Trường hợp khác | D25: Status = enable
A26: GUI-SearchCB-08 | B26: [Sau]Button | C26: Nếu người quản lí đang ở trang cuối của danh sách hoặc các bản ghi hiện tại có ít hơn hoặc bằng 10 bản ghi. | D26: Status = disable
C27: Trường hợp khác | D27: Status = enable
A28: GUI-SearchCB-09 | B28: [Cuối]Button | C28: Nếu người quản lí đang ở trang cuối của danh sách hoặc các bản ghi hiện tại có ít hơn hoặc bằng 10 bản ghi. | D28: Status = disable
C29: Trường hợp khác | D29: Status = enable
B30: Check FUNC-Tìm kiếm cán bộ
A31: FUNC-SearchCB-01 | B31: Mở màn hình tìm kiếm thành công | C31: Tại Menu Ứng dụng: 1. Click [Cán bộ] 2. Click [Danh sách cán bộ]. | D31: Mở màn hình danh sách cán bộ (refer sheet Layout QL cán bộ)
A32: FUNC-SearchCB-02 | B32: Tìm kiếm thành công nhưng không có kết quả tìm thấy | C32: Tại màn hình tìm kiếm: 1. Nhập vào dữ liệu không tồn tại trong hệ thống. (Ví dụ: Nhập vào tên Nguyễn Văn Anh không tồn tại trong hệ thống) 2. Nhấn Enter | D32: Hiển thị thông báo: "Không tìm thấy dữ liệu phù hợp!"
A33: FUNC-SearchCB-03 | B33: Tìm kiếm thành công nhưng không nhập dữ liệu | C33: Tại màn hình tìm kiếm: 1. Không nhập dữ liệu vào. 2. Nhấn Enter | D33: Hiển thị danh sách tất cả cán bộ trong hệ thống.
A34: FUNC-SearchCB-04 | B34: Tìm kiếm thành công với dữ liệu được nhập vào là họ tên | C34: Tại màn hình tìm kiếm: 1. Nhập vào tên cán bộ cần tìm. 2. Nhấn Enter. | D34: Hiển thị danh sách cán bộ phù hợp với họ tên nhập vào.
A35: FUNC-SearchCB-05 | B35: Tìm kiếm thành công với dữ liệu được nhập vào là Ngày sinh | C35: Tại màn hình tìm kiếm: 1. Nhập vào Ngày sinh cần tìm. 2. Nhấn Enter. | D35: Hiển thị danh sách cán bộ phù hợp với Ngày sinh nhập vào.
B36: Function : Thêm cán bộ
B37: Check GUI-Thêm cán bộ
A38: GUI-ThemCB-01 | B38: [Tên cán bộ] Textbox | C38: Nhập vào tên cán bộ cần thêm. | D38: Status = enable Default = blank Max-length = 100
A39: GUI-ThemCB-02 | B39: [Giới tính] Combobox | C39: Lựa chọn giới tính cán bộ. | D39: Status = enable Max-length = 20
A40: GUI-ThemCB-03 | B40: [Ngày sinh] Datechoose | C40: Lựa chọn ngày sinh cán bộ. | D40: Status = enable
A41: GUI-ThemCB-04 | B41: [Số điện thoại] Textbox | C41: Nhập vào số điện thoại cán bộ. | D41: Status = enable Default = blank Max-length = 50
A42: GUI-ThemCB-05 | B42: [Hình ảnh] Choosefile | C42: Chọn hình ảnh đại diện. | D42: Status = enable
...

Sheet Layout QL cán bộ

Sheet Test Report
B1: TEST REPORT
B3: Project Name | C3: Quản lí tiêm chủng cho gia súc và gia cầm cho các hộ chăn nuôi của quận/huyện | E3: Creator | H3: Võ Văn Hoan
B4: Project Code | C4: SE04 | E4: Reviewer/Approver
B5: Document Code | C5: =C4&"_"&"Test Report"&"_"&"v2.0" -> SE04_Test Report_v2.0 | E5: Issue Date | H5: 42982
B6: Notes
B10: No | C10: Module code | D10: Pass | E10: Fail | F10: Untested | G10: N/A | H10: Number of test cases
B11: 1 | C11: ='Quản lí cán bộ'!B2 -> Quản lí cán bộ | D11: ='Quản lí cán bộ'!A6 -> 0 | E11: ='Quản lí cán bộ'!B6 -> 0 | F11: ='Quản lí cán bộ'!C6 -> 104 | G11: ='Quản lí cán bộ'!D6 -> 0 | H11: ='Quản lí cán bộ'!E6 -> 104
B12: 2
B13: 3
B14: 4
C15: Sub total | D15: =SUM(D11:D14) -> 0 | E15: =SUM(E11:E14) -> 0 | F15: =SUM(F11:F14) -> 104 | G15: =SUM(G11:G14) -> 0 | H15: =SUM(H11:H14) -> 104
C17: Test coverage | E17: =(D15+E15)*100/(H15-G15) -> 0 | F17: %
C18: Test successful coverage | E18: =D15*100/(H15-G15) -> 0 | F18: %
